{
 "cells": [
  {
   "cell_type": "code",
   "execution_count": 1,
   "metadata": {},
   "outputs": [],
   "source": [
    "%load_ext tensorboard"
   ]
  },
  {
   "cell_type": "code",
   "execution_count": 2,
   "metadata": {},
   "outputs": [],
   "source": [
    "import tensorflow as tf\n",
    "import datetime"
   ]
  },
  {
   "cell_type": "code",
   "execution_count": 3,
   "metadata": {},
   "outputs": [],
   "source": [
    "# # clear any logs from previous runs\n",
    "# !del logs"
   ]
  },
  {
   "cell_type": "code",
   "execution_count": 4,
   "metadata": {},
   "outputs": [],
   "source": [
    "mnist = tf.keras.datasets.mnist\n",
    "\n",
    "(x_train, y_train),(x_test, y_test) = mnist.load_data()\n",
    "x_train, x_test = x_train / 255.0, x_test / 255.0\n",
    "\n",
    "def create_model():\n",
    "    return tf.keras.models.Sequential([\n",
    "        tf.keras.layers.Flatten(input_shape=(28, 28)),\n",
    "        tf.keras.layers.Dense(512, activation='relu'),\n",
    "        tf.keras.layers.Dropout(0.2),\n",
    "        tf.keras.layers.Dense(10, activation='softmax')\n",
    "  ])\n"
   ]
  },
  {
   "cell_type": "code",
   "execution_count": 5,
   "metadata": {},
   "outputs": [
    {
     "name": "stderr",
     "output_type": "stream",
     "text": [
      "WARNING: Logging before flag parsing goes to stderr.\n",
      "W0519 06:53:19.232292 18092 deprecation.py:506] From C:\\installs\\Anaconda\\envs\\tf_gpu\\lib\\site-packages\\tensorflow\\python\\ops\\init_ops.py:1251: calling VarianceScaling.__init__ (from tensorflow.python.ops.init_ops) with dtype is deprecated and will be removed in a future version.\n",
      "Instructions for updating:\n",
      "Call initializer instance with the dtype argument instead of passing it to the constructor\n"
     ]
    },
    {
     "name": "stdout",
     "output_type": "stream",
     "text": [
      "Train on 60000 samples, validate on 10000 samples\n",
      "Epoch 1/5\n"
     ]
    },
    {
     "ename": "InternalError",
     "evalue": "2 root error(s) found.\n  (0) Internal: Blas GEMM launch failed : a.shape=(32, 784), b.shape=(784, 512), m=32, n=512, k=784\n\t [[{{node dense/MatMul}}]]\n\t [[metrics/acc/Identity/_61]]\n  (1) Internal: Blas GEMM launch failed : a.shape=(32, 784), b.shape=(784, 512), m=32, n=512, k=784\n\t [[{{node dense/MatMul}}]]\n0 successful operations.\n0 derived errors ignored.",
     "output_type": "error",
     "traceback": [
      "\u001b[1;31m---------------------------------------------------------------------------\u001b[0m",
      "\u001b[1;31mInternalError\u001b[0m                             Traceback (most recent call last)",
      "\u001b[1;32m<ipython-input-5-cd96cbab2d6a>\u001b[0m in \u001b[0;36m<module>\u001b[1;34m\u001b[0m\n\u001b[0;32m     11\u001b[0m           \u001b[0mepochs\u001b[0m\u001b[1;33m=\u001b[0m\u001b[1;36m5\u001b[0m\u001b[1;33m,\u001b[0m\u001b[1;33m\u001b[0m\u001b[1;33m\u001b[0m\u001b[0m\n\u001b[0;32m     12\u001b[0m           \u001b[0mvalidation_data\u001b[0m\u001b[1;33m=\u001b[0m\u001b[1;33m(\u001b[0m\u001b[0mx_test\u001b[0m\u001b[1;33m,\u001b[0m \u001b[0my_test\u001b[0m\u001b[1;33m)\u001b[0m\u001b[1;33m,\u001b[0m\u001b[1;33m\u001b[0m\u001b[1;33m\u001b[0m\u001b[0m\n\u001b[1;32m---> 13\u001b[1;33m           callbacks=[tensorboard_callback])\n\u001b[0m",
      "\u001b[1;32mC:\\installs\\Anaconda\\envs\\tf_gpu\\lib\\site-packages\\tensorflow\\python\\keras\\engine\\training.py\u001b[0m in \u001b[0;36mfit\u001b[1;34m(self, x, y, batch_size, epochs, verbose, callbacks, validation_split, validation_data, shuffle, class_weight, sample_weight, initial_epoch, steps_per_epoch, validation_steps, validation_freq, max_queue_size, workers, use_multiprocessing, **kwargs)\u001b[0m\n\u001b[0;32m    778\u001b[0m           \u001b[0mvalidation_steps\u001b[0m\u001b[1;33m=\u001b[0m\u001b[0mvalidation_steps\u001b[0m\u001b[1;33m,\u001b[0m\u001b[1;33m\u001b[0m\u001b[1;33m\u001b[0m\u001b[0m\n\u001b[0;32m    779\u001b[0m           \u001b[0mvalidation_freq\u001b[0m\u001b[1;33m=\u001b[0m\u001b[0mvalidation_freq\u001b[0m\u001b[1;33m,\u001b[0m\u001b[1;33m\u001b[0m\u001b[1;33m\u001b[0m\u001b[0m\n\u001b[1;32m--> 780\u001b[1;33m           steps_name='steps_per_epoch')\n\u001b[0m\u001b[0;32m    781\u001b[0m \u001b[1;33m\u001b[0m\u001b[0m\n\u001b[0;32m    782\u001b[0m   def evaluate(self,\n",
      "\u001b[1;32mC:\\installs\\Anaconda\\envs\\tf_gpu\\lib\\site-packages\\tensorflow\\python\\keras\\engine\\training_arrays.py\u001b[0m in \u001b[0;36mmodel_iteration\u001b[1;34m(model, inputs, targets, sample_weights, batch_size, epochs, verbose, callbacks, val_inputs, val_targets, val_sample_weights, shuffle, initial_epoch, steps_per_epoch, validation_steps, validation_freq, mode, validation_in_fit, prepared_feed_values_from_dataset, steps_name, **kwargs)\u001b[0m\n\u001b[0;32m    361\u001b[0m \u001b[1;33m\u001b[0m\u001b[0m\n\u001b[0;32m    362\u001b[0m         \u001b[1;31m# Get outputs.\u001b[0m\u001b[1;33m\u001b[0m\u001b[1;33m\u001b[0m\u001b[1;33m\u001b[0m\u001b[0m\n\u001b[1;32m--> 363\u001b[1;33m         \u001b[0mbatch_outs\u001b[0m \u001b[1;33m=\u001b[0m \u001b[0mf\u001b[0m\u001b[1;33m(\u001b[0m\u001b[0mins_batch\u001b[0m\u001b[1;33m)\u001b[0m\u001b[1;33m\u001b[0m\u001b[1;33m\u001b[0m\u001b[0m\n\u001b[0m\u001b[0;32m    364\u001b[0m         \u001b[1;32mif\u001b[0m \u001b[1;32mnot\u001b[0m \u001b[0misinstance\u001b[0m\u001b[1;33m(\u001b[0m\u001b[0mbatch_outs\u001b[0m\u001b[1;33m,\u001b[0m \u001b[0mlist\u001b[0m\u001b[1;33m)\u001b[0m\u001b[1;33m:\u001b[0m\u001b[1;33m\u001b[0m\u001b[1;33m\u001b[0m\u001b[0m\n\u001b[0;32m    365\u001b[0m           \u001b[0mbatch_outs\u001b[0m \u001b[1;33m=\u001b[0m \u001b[1;33m[\u001b[0m\u001b[0mbatch_outs\u001b[0m\u001b[1;33m]\u001b[0m\u001b[1;33m\u001b[0m\u001b[1;33m\u001b[0m\u001b[0m\n",
      "\u001b[1;32mC:\\installs\\Anaconda\\envs\\tf_gpu\\lib\\site-packages\\tensorflow\\python\\keras\\backend.py\u001b[0m in \u001b[0;36m__call__\u001b[1;34m(self, inputs)\u001b[0m\n\u001b[0;32m   3290\u001b[0m \u001b[1;33m\u001b[0m\u001b[0m\n\u001b[0;32m   3291\u001b[0m     fetched = self._callable_fn(*array_vals,\n\u001b[1;32m-> 3292\u001b[1;33m                                 run_metadata=self.run_metadata)\n\u001b[0m\u001b[0;32m   3293\u001b[0m     \u001b[0mself\u001b[0m\u001b[1;33m.\u001b[0m\u001b[0m_call_fetch_callbacks\u001b[0m\u001b[1;33m(\u001b[0m\u001b[0mfetched\u001b[0m\u001b[1;33m[\u001b[0m\u001b[1;33m-\u001b[0m\u001b[0mlen\u001b[0m\u001b[1;33m(\u001b[0m\u001b[0mself\u001b[0m\u001b[1;33m.\u001b[0m\u001b[0m_fetches\u001b[0m\u001b[1;33m)\u001b[0m\u001b[1;33m:\u001b[0m\u001b[1;33m]\u001b[0m\u001b[1;33m)\u001b[0m\u001b[1;33m\u001b[0m\u001b[1;33m\u001b[0m\u001b[0m\n\u001b[0;32m   3294\u001b[0m     output_structure = nest.pack_sequence_as(\n",
      "\u001b[1;32mC:\\installs\\Anaconda\\envs\\tf_gpu\\lib\\site-packages\\tensorflow\\python\\client\\session.py\u001b[0m in \u001b[0;36m__call__\u001b[1;34m(self, *args, **kwargs)\u001b[0m\n\u001b[0;32m   1456\u001b[0m         ret = tf_session.TF_SessionRunCallable(self._session._session,\n\u001b[0;32m   1457\u001b[0m                                                \u001b[0mself\u001b[0m\u001b[1;33m.\u001b[0m\u001b[0m_handle\u001b[0m\u001b[1;33m,\u001b[0m \u001b[0margs\u001b[0m\u001b[1;33m,\u001b[0m\u001b[1;33m\u001b[0m\u001b[1;33m\u001b[0m\u001b[0m\n\u001b[1;32m-> 1458\u001b[1;33m                                                run_metadata_ptr)\n\u001b[0m\u001b[0;32m   1459\u001b[0m         \u001b[1;32mif\u001b[0m \u001b[0mrun_metadata\u001b[0m\u001b[1;33m:\u001b[0m\u001b[1;33m\u001b[0m\u001b[1;33m\u001b[0m\u001b[0m\n\u001b[0;32m   1460\u001b[0m           \u001b[0mproto_data\u001b[0m \u001b[1;33m=\u001b[0m \u001b[0mtf_session\u001b[0m\u001b[1;33m.\u001b[0m\u001b[0mTF_GetBuffer\u001b[0m\u001b[1;33m(\u001b[0m\u001b[0mrun_metadata_ptr\u001b[0m\u001b[1;33m)\u001b[0m\u001b[1;33m\u001b[0m\u001b[1;33m\u001b[0m\u001b[0m\n",
      "\u001b[1;31mInternalError\u001b[0m: 2 root error(s) found.\n  (0) Internal: Blas GEMM launch failed : a.shape=(32, 784), b.shape=(784, 512), m=32, n=512, k=784\n\t [[{{node dense/MatMul}}]]\n\t [[metrics/acc/Identity/_61]]\n  (1) Internal: Blas GEMM launch failed : a.shape=(32, 784), b.shape=(784, 512), m=32, n=512, k=784\n\t [[{{node dense/MatMul}}]]\n0 successful operations.\n0 derived errors ignored."
     ]
    }
   ],
   "source": [
    "model = create_model()\n",
    "model.compile(optimizer='adam',\n",
    "              loss='sparse_categorical_crossentropy',\n",
    "              metrics=['accuracy'])\n",
    "\n",
    "log_dir = \"logs/fit/\" + datetime.datetime.now().strftime(\"%Y%m%d-%H%M%S\")\n",
    "tensorboard_callback = tf.keras.callbacks.TensorBoard(log_dir=log_dir, histogram_freq=1)\n",
    "\n",
    "model.fit(x=x_train, \n",
    "          y=y_train, \n",
    "          epochs=5, \n",
    "          validation_data=(x_test, y_test), \n",
    "          callbacks=[tensorboard_callback])\n",
    "\n",
    "# error ref\n",
    "# https://stackoverflow.com/questions/43990046/tensorflow-blas-gemm-launch-failed\n"
   ]
  },
  {
   "cell_type": "code",
   "execution_count": null,
   "metadata": {},
   "outputs": [],
   "source": [
    "%tensorboard --logdir logs/fit\n",
    "\n",
    "# this is supposed to open a tensorboard server at http://localhost:6006/"
   ]
  }
 ],
 "metadata": {
  "kernelspec": {
   "display_name": "Python (tf_gpu)",
   "language": "python",
   "name": "tf_gpu"
  },
  "language_info": {
   "codemirror_mode": {
    "name": "ipython",
    "version": 3
   },
   "file_extension": ".py",
   "mimetype": "text/x-python",
   "name": "python",
   "nbconvert_exporter": "python",
   "pygments_lexer": "ipython3",
   "version": "3.7.4"
  }
 },
 "nbformat": 4,
 "nbformat_minor": 2
}
